<?xml version="1.0" ?>
<!-- =================================================================================== -->
<!-- |    This document was autogenerated by xacro from panda_arm_hand.urdf.xacro      | -->
<!-- |    EDITING THIS FILE BY HAND IS NOT RECOMMENDED                                 | -->
<!-- =================================================================================== -->
<robot name="panda" xmlns:xacro="http://www.ros.org/wiki/xacro">
  
  <material name="white">
    <color rgba="1 1 1 1"/>
  </material>

  <material name="grey">
    <color rgba="0.8 0.8 0.8 1"/>
  </material>

  <!-- this link is the base link, indexed as -1 in pyBullet -->
  <link name="panda_link0">
    <inertial>
<!--         <mass value="2.92" /> -->
        <mass value="0" />
        <origin xyz="-0.025566 -2.88e-05 0.057332" rpy="0 0 0" />
        <inertia ixx="0.00782229414331" ixy="-1.56191622996e-05" ixz="-0.00126005738123" iyy="0.0109027971813" iyz="1.08233858202e-05" izz="0.0102355503949" />
    </inertial>
    <visual>
      <origin rpy="0 0 0" xyz="0 0 0"/>
      <geometry>
        <mesh filename="stl/visual/link0.dae"/>
      </geometry>
      <material name="white"/>
    </visual>
    <collision>
      <origin rpy="0 0 0" xyz="0 0 0"/>
      <geometry>
        <mesh filename="stl/collision/link0.stl"/>
      </geometry>
    </collision>
  </link>

  <joint name="panda_joint1" type="revolute">
    <safety_controller k_position="100.0" k_velocity="40.0" soft_lower_limit="-2.8973" soft_upper_limit="2.8973"/>
    <origin rpy="0 0 0" xyz="0 0 0.333"/>
    <parent link="panda_link0"/>
    <child link="panda_link1"/>
    <axis xyz="0 0 1"/>
    <limit effort="87" lower="-2.8973" upper="2.8973" velocity="2.1750"/>
  </joint>
  
  <link name="panda_link1">
    <inertial>
      <mass value="2.74" />
      <origin xyz="0 -0.0324958 -0.0675818" rpy="0 0 0" />
      <inertia ixx="0.0180416958283" ixy="0.0" ixz="0.0" iyy="0.0159136071891" iyz="0.0046758424612" izz="0.00620690827127" />
    </inertial>    
    <visual>
      <origin rpy="0 0 0" xyz="0 0 0"/>
      <geometry>
        <mesh filename="stl/visual/link1.dae"/>
      </geometry>
      <material name="white"/>
    </visual>
    <collision>
      <origin rpy="0 0 0" xyz="0 0 0"/>
      <geometry>
        <mesh filename="stl/collision/link1.stl"/>
      </geometry>
    </collision>
  </link>

  <joint name="panda_joint2" type="revolute">
    <safety_controller k_position="100.0" k_velocity="40.0" soft_lower_limit="-1.7628" soft_upper_limit="1.7628"/>
    <origin rpy="-1.5707963267948966 0 0" xyz="0 0 0"/>
    <parent link="panda_link1"/>
    <child link="panda_link2"/>
    <axis xyz="0 0 1"/>
    <limit effort="87" lower="-1.7628" upper="1.7628" velocity="2.1750"/>
  </joint>
    
  <link name="panda_link2">
    <inertial>
      <mass value="2.74" />
      <origin xyz="0 -0.06861 0.0322285" rpy="0 0 0" />
      <inertia ixx="0.0182856182281" ixy="0.0" ixz="0.0" iyy="0.00621358421175" iyz="-0.00472844221905" izz="0.0161514346309" />
    </inertial>
    <visual>
      <origin rpy="0 0 0" xyz="0 0 0"/>
      <geometry>
        <mesh filename="stl/visual/link2.dae"/>
      </geometry>
      <material name="white"/>
    </visual>
    <collision>
      <origin rpy="0 0 0" xyz="0 0 0"/>
      <geometry>
        <mesh filename="stl/collision/link2.stl"/>
      </geometry>
    </collision>
  </link>
  
  <joint name="panda_joint3" type="revolute">
    <safety_controller k_position="100.0" k_velocity="40.0" soft_lower_limit="-2.8973" soft_upper_limit="2.8973"/>
    <origin rpy="1.5707963267948966 0 0" xyz="0 -0.316 0"/>
    <parent link="panda_link2"/>
    <child link="panda_link3"/>
    <axis xyz="0 0 1"/>
    <limit effort="87" lower="-2.8973" upper="2.8973" velocity="2.1750"/>
  </joint>
  
  <link name="panda_link3">
    <inertial>
      <mass value="2.38" />
      <origin xyz="0.0469893 0.0316374 -0.031704" rpy="0 0 0" />
      <inertia ixx="0.00771376630908" ixy="-0.00248490625138" ixz="-0.00332147581033" iyy="0.00989108008727" iyz="-0.00217796151484" izz="0.00811723558464" />
    </inertial>
    <visual>
      <origin rpy="0 0 0" xyz="0 0 0"/>
      <geometry>
        <mesh filename="stl/visual/link3.dae"/>
      </geometry>
      <material name="white"/>
    </visual>
    <collision>
      <origin rpy="0 0 0" xyz="0 0 0"/>
      <geometry>
        <mesh filename="stl/collision/link3.stl"/>
      </geometry>
    </collision>
  </link>
  
  <joint name="panda_joint4" type="revolute">
    <safety_controller k_position="100.0" k_velocity="40.0" soft_lower_limit="-3.0718" soft_upper_limit="-0.0698"/>
    <origin rpy="1.5707963267948966 0 0" xyz="0.0825 0 0"/>
    <parent link="panda_link3"/>
    <child link="panda_link4"/>
    <axis xyz="0 0 1"/>
    <limit effort="87" lower="-3.0718" upper="-0.0698" velocity="2.1750"/>
  </joint>
  
  <link name="panda_link4">
    <inertial>
      <mass value="2.38" />
      <origin xyz="-0.0360446 0.0336853 0.031882" rpy="0 0 0" />
      <inertia ixx="0.00799663881132" ixy="0.00347095570217" ixz="-0.00241222942995" iyy="0.00825390705278" iyz="0.00235774044121" izz="0.0102515004345" />
    </inertial>
    <visual>
      <origin rpy="0 0 0" xyz="0 0 0"/>
      <geometry>
        <mesh filename="stl/visual/link4.dae"/>
      </geometry>
      <material name="white"/>
    </visual>
    <collision>
      <origin rpy="0 0 0" xyz="0 0 0"/>
      <geometry>
        <mesh filename="stl/collision/link4.stl"/>
      </geometry>
    </collision>
  </link>
  
  <joint name="panda_joint5" type="revolute">
    <safety_controller k_position="100.0" k_velocity="40.0" soft_lower_limit="-2.8973" soft_upper_limit="2.8973"/>
    <origin rpy="-1.5707963267948966 0 0" xyz="-0.0825 0.384 0"/>
    <parent link="panda_link4"/>
    <child link="panda_link5"/>
    <axis xyz="0 0 1"/>
    <limit effort="12" lower="-2.8973" upper="2.8973" velocity="2.6100"/>
  </joint>
  
  <link name="panda_link5">
    <inertial>
      <mass value="2.74" />
      <origin xyz="0 0.0610427 -0.104176" rpy="0 0 0" />
      <inertia ixx="0.030371374513" ixy="6.50283587108e-07" ixz="-1.05129179916e-05" iyy="0.0288752887402" iyz="-0.00775653445787" izz="0.00444134056164" />
    </inertial>
    <visual>
      <origin rpy="0 0 0" xyz="0 0 0"/>
      <geometry>
        <mesh filename="stl/visual/link5.dae"/>
      </geometry>
      <material name="white"/>
    </visual>
    <collision>
      <origin rpy="0 0 0" xyz="0 0 0"/>
      <geometry>
        <mesh filename="stl/collision/link5.stl"/>
      </geometry>
    </collision>
  </link>
  
  <joint name="panda_joint6" type="revolute">
    <safety_controller k_position="100.0" k_velocity="40.0" soft_lower_limit="-0.0175" soft_upper_limit="3.7525"/>
    <origin rpy="1.5707963267948966 0 0" xyz="0 0 0"/>
    <parent link="panda_link5"/>
    <child link="panda_link6"/>
    <axis xyz="0 0 1"/>
    <limit effort="12" lower="-0.0175" upper="3.7525" velocity="2.6100"/>
  </joint>
  
  <link name="panda_link6">
    <inertial>
      <mass value="1.55" />
      <origin xyz="0.0510509 0.009108 0.0106343" rpy="0 0 0" />
      <inertia ixx="0.00303336450376" ixy="-0.000437276865508" ixz="0.000629257294877" iyy="0.00404479911567" iyz="0.000130472021025" izz="0.00558234286039" />
    </inertial>
    <visual>
      <origin rpy="0 0 0" xyz="0 0 0"/>
      <geometry>
        <mesh filename="stl/visual/link6.dae"/>
      </geometry>
      <material name="white"/>
    </visual>
    <collision>
      <origin rpy="0 0 0" xyz="0 0 0"/>
      <geometry>
        <mesh filename="stl/collision/link6.stl"/>
      </geometry>
    </collision>
  </link>
  
  <joint name="panda_joint7" type="revolute">
    <safety_controller k_position="100.0" k_velocity="40.0" soft_lower_limit="-2.8973" soft_upper_limit="2.8973"/>
    <origin rpy="1.5707963267948966 0 0" xyz="0.088 0 0"/>
    <parent link="panda_link6"/>
    <child link="panda_link7"/>
    <axis xyz="0 0 1"/>
    <limit effort="12" lower="-2.8973" upper="2.8973" velocity="2.6100"/>
  </joint>
  
  <link name="panda_link7">
    <inertial>
      <mass value="0.54" />
      <origin xyz="0.0109695 0.0107965 0.0650411" rpy="0 0 0" />
      <inertia ixx="0.000888868887021" ixy="-0.00012239074652" ixz="3.98699829666e-05" iyy="0.000888001373233" iyz="-9.33825115206e-05" izz="0.0007176834609" />
    </inertial>
    <visual>
      <origin rpy="0 0 0" xyz="0 0 0"/>
      <geometry>
        <mesh filename="stl/visual/link7.dae"/>
      </geometry>
      <material name="white"/>
    </visual>
    <collision>
      <origin rpy="0 0 0" xyz="0 0 0"/>
      <geometry>
        <mesh filename="stl/collision/link7.stl"/>
      </geometry>
    </collision>
  </link>
  
  <joint name="joint_to_hand" type="continuous">
    <parent link="panda_link7"/>
    <child link="panda_hand"/>
    <origin rpy="0 0 -0.7853981633974483" xyz="0 0 0.107"/>
    <dynamics damping="0.5"/>
    <axis xyz="0 0 1"/> 
  </joint>

  <link name="panda_hand">
    <inertial>
        <mass value="0.73" />
        <origin xyz="0 0.0015244 0.0275912" rpy="0 0 0" />
        <inertia ixx="0.00278560230025" ixy="0.0" ixz="0.0" iyy="0.000400033405336" iyz="0.0" izz="0.00256378041832" />
    </inertial>
    <visual>
      <origin rpy="0 0 0" xyz="0 0 0"/>
      <geometry>
        <mesh filename="stl/visual/hand.dae"/>
      </geometry>
      <material name="white"/>
    </visual>
    <collision>
      <origin rpy="0 0 0" xyz="0 0 0"/>
      <geometry>
        <mesh filename="stl/collision/hand.stl"/>
      </geometry>
    </collision>
  </link>

  <joint name="hand_to_peg" type="fixed">
    <parent link="panda_hand"/>
    <child link="peg"/>
    <axis xyz="0 0 1"/> 
  </joint>

    <link name="peg">
    <inertial>
      <origin rpy="0 0 0" xyz="0 0 0.24"/>
      <mass value="0.4"/>
      <inertia ixx="0.0094" ixy="0" ixz="0" iyy="0.0008" iyz="0" izz="0.0094"/>
    </inertial>
    <visual>
      <origin rpy="3.14159, 0, 0.57" xyz="0, 0, 0.148"/>
      <geometry>
        <mesh filename="stl/collision/peg.stl" scale="0.001 0.001 0.001"/>
      </geometry>
       <material name="white" />
    </visual>
    <collision>
      <origin rpy="3.14159, 0, 0.57" xyz="0, 0, 0.148"/>
      <geometry>
           <mesh filename="stl/collision/peg.stl" scale="0.001 0.001 0.001"/>
      </geometry>
    </collision>
  </link>



  
<!--   <link name="panda_link8"/>
  
  <joint name="panda_joint8" type="fixed">
    <origin rpy="0 0 0" xyz="0 0 0.107"/>
    <parent link="panda_link7"/>
    <child link="panda_link8"/>
    <axis xyz="0 0 0"/>
  </joint> -->
  
<!--   <joint name="panda_hand_joint" type="fixed">
    <parent link="panda_link8"/>
    <child link="panda_hand"/>
    <origin rpy="0 0 -0.7853981633974483" xyz="0 0 0"/>
  </joint>
  
  <link name="panda_hand">
    <inertial>
        <mass value="0.73" />
        <origin xyz="0 0.0015244 0.0275912" rpy="0 0 0" />
        <inertia ixx="0.00278560230025" ixy="0.0" ixz="0.0" iyy="0.000400033405336" iyz="0.0" izz="0.00256378041832" />
    </inertial>
    <visual>
      <geometry>
        <mesh filename="stl/visual/hand.dae"/>
      </geometry>
      <material name="white"/>
    </visual>
    <collision>
      <geometry>
        <mesh filename="stl/collision/hand.stl"/>
      </geometry>
    </collision>
  </link> -->
    
<!--   <link name="peg">
    <inertial>
      <origin rpy="0 0 0" xyz="0 0 0.24"/>
      <mass value="0.4"/>
      <inertia ixx="0.0094" ixy="0" ixz="0" iyy="0.0008" iyz="0" izz="0.0094"/>
    </inertial>
    <visual>
      <origin rpy="3.14159, 0, 0.57" xyz="0, 0, 0.148"/>
      <geometry>
        <mesh filename="stl/collision/peg.stl" scale="0.001 0.001 0.001"/>
      </geometry>
       <material name="white" />
    </visual>
    <collision>
      <origin rpy="3.14159, 0, 0.57" xyz="0, 0, 0.148"/>
      <geometry>
           <mesh filename="stl/collision/peg.stl" scale="0.001 0.001 0.001"/>
      </geometry>
    </collision>
  </link>

  <joint name="hand_to_peg" type="continuous">
    <parent link="panda_hand"/>
    <child link="peg"/>
    <axis xyz="0 0 1"/>
    <dynamics damping="0.5"/>
  </joint> -->

</robot>

